2024-08-16 11:30:15,351 - telethon.network.mtprotosender - INFO - Disconnecting from 149.154.167.92:443/TcpFull...
2024-08-16 11:30:15,352 - telethon.network.mtprotosender - INFO - Disconnection from 149.154.167.92:443/TcpFull complete!
2024-08-16 11:30:15,353 - telethon.network.mtprotosender - INFO - Not disconnecting (already have no connection)
2024-08-16 11:33:43,197 - telethon.network.mtprotosender - INFO - Disconnecting from 149.154.167.92:443/TcpFull...
2024-08-16 11:33:43,198 - telethon.network.mtprotosender - INFO - Disconnection from 149.154.167.92:443/TcpFull complete!
2024-08-16 11:33:43,199 - telethon.network.mtprotosender - INFO - Not disconnecting (already have no connection)
2024-08-16 11:35:21,558 - telethon.network.mtprotosender - INFO - Disconnecting from 149.154.167.92:443/TcpFull...
2024-08-16 11:35:21,559 - telethon.network.mtprotosender - INFO - Disconnection from 149.154.167.92:443/TcpFull complete!
2024-08-16 11:35:21,560 - telethon.network.mtprotosender - INFO - Not disconnecting (already have no connection)
2024-08-16 11:36:00,025 - telethon.network.mtprotosender - INFO - Disconnecting from 149.154.167.92:443/TcpFull...
2024-08-16 11:36:00,026 - telethon.network.mtprotosender - INFO - Disconnection from 149.154.167.92:443/TcpFull complete!
2024-08-16 11:36:00,027 - telethon.network.mtprotosender - INFO - Not disconnecting (already have no connection)
2024-08-16 11:36:52,496 - telethon.network.mtprotosender - INFO - Disconnecting from 149.154.167.92:443/TcpFull...
2024-08-16 11:36:52,497 - telethon.network.mtprotosender - INFO - Disconnection from 149.154.167.92:443/TcpFull complete!
2024-08-16 11:36:52,497 - telethon.network.mtprotosender - INFO - Not disconnecting (already have no connection)
2024-08-16 11:49:07,282 - telethon.network.mtprotosender - INFO - Disconnecting from 149.154.167.92:443/TcpFull...
2024-08-16 11:49:07,283 - telethon.network.mtprotosender - INFO - Disconnection from 149.154.167.92:443/TcpFull complete!
2024-08-16 11:49:07,284 - telethon.network.mtprotosender - INFO - Not disconnecting (already have no connection)
2024-08-16 11:49:21,817 - telethon.network.mtprotosender - INFO - Disconnecting from 149.154.167.92:443/TcpFull...
2024-08-16 11:49:21,818 - telethon.network.mtprotosender - INFO - Disconnection from 149.154.167.92:443/TcpFull complete!
2024-08-16 11:49:21,819 - telethon.network.mtprotosender - INFO - Not disconnecting (already have no connection)
2024-08-16 11:50:08,738 - telethon.network.mtprotosender - INFO - Disconnecting from 149.154.167.92:443/TcpFull...
2024-08-16 11:50:08,740 - telethon.network.mtprotosender - INFO - Disconnection from 149.154.167.92:443/TcpFull complete!
2024-08-16 11:50:08,740 - telethon.network.mtprotosender - INFO - Not disconnecting (already have no connection)
2024-08-16 11:50:55,081 - telethon.network.mtprotosender - INFO - Disconnecting from 149.154.167.92:443/TcpFull...
2024-08-16 11:50:55,082 - telethon.network.mtprotosender - INFO - Disconnection from 149.154.167.92:443/TcpFull complete!
2024-08-16 11:50:55,083 - telethon.network.mtprotosender - INFO - Not disconnecting (already have no connection)
2024-08-16 11:52:24,673 - telethon.network.mtprotosender - INFO - Disconnecting from 149.154.167.92:443/TcpFull...
2024-08-16 11:52:24,674 - telethon.network.mtprotosender - INFO - Disconnection from 149.154.167.92:443/TcpFull complete!
2024-08-16 11:52:24,675 - telethon.network.mtprotosender - INFO - Not disconnecting (already have no connection)
2024-08-16 11:53:40,618 - telethon.client.updates - ERROR - Unhandled exception on get_url
Traceback (most recent call last):
  File "/usr/lib/python3.11/urllib/request.py", line 1348, in do_open
    h.request(req.get_method(), req.selector, req.data, headers,
  File "/usr/lib/python3.11/http/client.py", line 1303, in request
    self._send_request(method, url, body, headers, encode_chunked)
  File "/usr/lib/python3.11/http/client.py", line 1349, in _send_request
    self.endheaders(body, encode_chunked=encode_chunked)
  File "/usr/lib/python3.11/http/client.py", line 1298, in endheaders
    self._send_output(message_body, encode_chunked=encode_chunked)
  File "/usr/lib/python3.11/http/client.py", line 1058, in _send_output
    self.send(msg)
  File "/usr/lib/python3.11/http/client.py", line 996, in send
    self.connect()
  File "/usr/lib/python3.11/http/client.py", line 1475, in connect
    self.sock = self._context.wrap_socket(self.sock,
                ^^^^^^^^^^^^^^^^^^^^^^^^^^^^^^^^^^^^
  File "/usr/lib/python3.11/ssl.py", line 517, in wrap_socket
    return self.sslsocket_class._create(
           ^^^^^^^^^^^^^^^^^^^^^^^^^^^^^
  File "/usr/lib/python3.11/ssl.py", line 1104, in _create
    self.do_handshake()
  File "/usr/lib/python3.11/ssl.py", line 1382, in do_handshake
    self._sslobj.do_handshake()
ConnectionResetError: [Errno 104] Connection reset by peer

During handling of the above exception, another exception occurred:

Traceback (most recent call last):
  File "/home/mohammad/Documents/code/projects/PlusSaver/.venv/lib/python3.11/site-packages/telethon/client/updates.py", line 570, in _dispatch_update
    await callback(event)
  File "/home/mohammad/Documents/code/projects/PlusSaver/modules/handlers/handlers.py", line 414, in get_url
    await client.send_file(event.chat_id, file=video, caption=yt_client.youtube_client.channel_url)
                                                              ^^^^^^^^^^^^^^^^^^^^^^^^^^^^^^^^^^^^
  File "/home/mohammad/Documents/code/projects/PlusSaver/.venv/lib/python3.11/site-packages/pytube/__main__.py", line 432, in channel_url
    return f'https://www.youtube.com/channel/{self.channel_id}'
                                              ^^^^^^^^^^^^^^^
  File "/home/mohammad/Documents/code/projects/PlusSaver/.venv/lib/python3.11/site-packages/pytube/__main__.py", line 424, in channel_id
    return self.vid_info.get('videoDetails', {}).get('channelId', None)
           ^^^^^^^^^^^^^
  File "/home/mohammad/Documents/code/projects/PlusSaver/.venv/lib/python3.11/site-packages/pytube/__main__.py", line 246, in vid_info
    innertube_response = innertube.player(self.video_id)
                         ^^^^^^^^^^^^^^^^^^^^^^^^^^^^^^^
  File "/home/mohammad/Documents/code/projects/PlusSaver/.venv/lib/python3.11/site-packages/pytube/innertube.py", line 448, in player
    return self._call_api(endpoint, query, self.base_data)
           ^^^^^^^^^^^^^^^^^^^^^^^^^^^^^^^^^^^^^^^^^^^^^^^
  File "/home/mohammad/Documents/code/projects/PlusSaver/.venv/lib/python3.11/site-packages/pytube/innertube.py", line 390, in _call_api
    response = request._execute_request(
               ^^^^^^^^^^^^^^^^^^^^^^^^^
  File "/home/mohammad/Documents/code/projects/PlusSaver/.venv/lib/python3.11/site-packages/pytube/request.py", line 37, in _execute_request
    return urlopen(request, timeout=timeout)  # nosec
           ^^^^^^^^^^^^^^^^^^^^^^^^^^^^^^^^^
  File "/usr/lib/python3.11/urllib/request.py", line 216, in urlopen
    return opener.open(url, data, timeout)
           ^^^^^^^^^^^^^^^^^^^^^^^^^^^^^^^
  File "/usr/lib/python3.11/urllib/request.py", line 519, in open
    response = self._open(req, data)
               ^^^^^^^^^^^^^^^^^^^^^
  File "/usr/lib/python3.11/urllib/request.py", line 536, in _open
    result = self._call_chain(self.handle_open, protocol, protocol +
             ^^^^^^^^^^^^^^^^^^^^^^^^^^^^^^^^^^^^^^^^^^^^^^^^^^^^^^^
  File "/usr/lib/python3.11/urllib/request.py", line 496, in _call_chain
    result = func(*args)
             ^^^^^^^^^^^
  File "/usr/lib/python3.11/urllib/request.py", line 1391, in https_open
    return self.do_open(http.client.HTTPSConnection, req,
           ^^^^^^^^^^^^^^^^^^^^^^^^^^^^^^^^^^^^^^^^^^^^^^
  File "/usr/lib/python3.11/urllib/request.py", line 1351, in do_open
    raise URLError(err)
urllib.error.URLError: <urlopen error [Errno 104] Connection reset by peer>
2024-08-16 11:55:07,391 - telethon.network.mtprotosender - INFO - Disconnecting from 149.154.167.92:443/TcpFull...
2024-08-16 11:55:07,391 - telethon.network.mtprotosender - INFO - Disconnection from 149.154.167.92:443/TcpFull complete!
2024-08-16 11:55:07,392 - telethon.network.mtprotosender - INFO - Not disconnecting (already have no connection)
2024-08-16 11:55:27,376 - telethon.client.updates - ERROR - Unhandled exception on get_url
Traceback (most recent call last):
  File "/usr/lib/python3.11/urllib/request.py", line 1348, in do_open
    h.request(req.get_method(), req.selector, req.data, headers,
  File "/usr/lib/python3.11/http/client.py", line 1303, in request
    self._send_request(method, url, body, headers, encode_chunked)
  File "/usr/lib/python3.11/http/client.py", line 1349, in _send_request
    self.endheaders(body, encode_chunked=encode_chunked)
  File "/usr/lib/python3.11/http/client.py", line 1298, in endheaders
    self._send_output(message_body, encode_chunked=encode_chunked)
  File "/usr/lib/python3.11/http/client.py", line 1058, in _send_output
    self.send(msg)
  File "/usr/lib/python3.11/http/client.py", line 996, in send
    self.connect()
  File "/usr/lib/python3.11/http/client.py", line 1475, in connect
    self.sock = self._context.wrap_socket(self.sock,
                ^^^^^^^^^^^^^^^^^^^^^^^^^^^^^^^^^^^^
  File "/usr/lib/python3.11/ssl.py", line 517, in wrap_socket
    return self.sslsocket_class._create(
           ^^^^^^^^^^^^^^^^^^^^^^^^^^^^^
  File "/usr/lib/python3.11/ssl.py", line 1104, in _create
    self.do_handshake()
  File "/usr/lib/python3.11/ssl.py", line 1382, in do_handshake
    self._sslobj.do_handshake()
ConnectionResetError: [Errno 104] Connection reset by peer

During handling of the above exception, another exception occurred:

Traceback (most recent call last):
  File "/home/mohammad/Documents/code/projects/PlusSaver/modules/downloaders/youtube.py", line 43, in download_video
    video = self.youtube_client.streams.get_by_resolution(resolution).download(r'./youtube/videos/')
            ^^^^^^^^^^^^^^^^^^^^^^^^^^^
  File "/home/mohammad/Documents/code/projects/PlusSaver/.venv/lib/python3.11/site-packages/pytube/__main__.py", line 295, in streams
    self.check_availability()
  File "/home/mohammad/Documents/code/projects/PlusSaver/.venv/lib/python3.11/site-packages/pytube/__main__.py", line 210, in check_availability
    status, messages = extract.playability_status(self.watch_html)
                                                  ^^^^^^^^^^^^^^^
  File "/home/mohammad/Documents/code/projects/PlusSaver/.venv/lib/python3.11/site-packages/pytube/__main__.py", line 102, in watch_html
    self._watch_html = request.get(url=self.watch_url)
                       ^^^^^^^^^^^^^^^^^^^^^^^^^^^^^^^
  File "/home/mohammad/Documents/code/projects/PlusSaver/.venv/lib/python3.11/site-packages/pytube/request.py", line 53, in get
    response = _execute_request(url, headers=extra_headers, timeout=timeout)
               ^^^^^^^^^^^^^^^^^^^^^^^^^^^^^^^^^^^^^^^^^^^^^^^^^^^^^^^^^^^^^
  File "/home/mohammad/Documents/code/projects/PlusSaver/.venv/lib/python3.11/site-packages/pytube/request.py", line 37, in _execute_request
    return urlopen(request, timeout=timeout)  # nosec
           ^^^^^^^^^^^^^^^^^^^^^^^^^^^^^^^^^
  File "/usr/lib/python3.11/urllib/request.py", line 216, in urlopen
    return opener.open(url, data, timeout)
           ^^^^^^^^^^^^^^^^^^^^^^^^^^^^^^^
  File "/usr/lib/python3.11/urllib/request.py", line 519, in open
    response = self._open(req, data)
               ^^^^^^^^^^^^^^^^^^^^^
  File "/usr/lib/python3.11/urllib/request.py", line 536, in _open
    result = self._call_chain(self.handle_open, protocol, protocol +
             ^^^^^^^^^^^^^^^^^^^^^^^^^^^^^^^^^^^^^^^^^^^^^^^^^^^^^^^
  File "/usr/lib/python3.11/urllib/request.py", line 496, in _call_chain
    result = func(*args)
             ^^^^^^^^^^^
  File "/usr/lib/python3.11/urllib/request.py", line 1391, in https_open
    return self.do_open(http.client.HTTPSConnection, req,
           ^^^^^^^^^^^^^^^^^^^^^^^^^^^^^^^^^^^^^^^^^^^^^^
  File "/usr/lib/python3.11/urllib/request.py", line 1351, in do_open
    raise URLError(err)
urllib.error.URLError: <urlopen error [Errno 104] Connection reset by peer>

During handling of the above exception, another exception occurred:

Traceback (most recent call last):
  File "/home/mohammad/Documents/code/projects/PlusSaver/.venv/lib/python3.11/site-packages/telethon/client/updates.py", line 570, in _dispatch_update
    await callback(event)
  File "/home/mohammad/Documents/code/projects/PlusSaver/modules/handlers/handlers.py", line 413, in get_url
    video = yt_client.download_video(resolution=YoutubeVideResoloution.R_480P.value)
            ^^^^^^^^^^^^^^^^^^^^^^^^^^^^^^^^^^^^^^^^^^^^^^^^^^^^^^^^^^^^^^^^^^^^^^^^
  File "/home/mohammad/Documents/code/projects/PlusSaver/modules/downloaders/youtube.py", line 46, in download_video
    print("Error in download_video method: ", list(e))
                                              ^^^^^^^
TypeError: 'URLError' object is not iterable
2024-08-16 11:56:33,250 - telethon.network.mtprotosender - INFO - Disconnecting from 149.154.167.92:443/TcpFull...
2024-08-16 11:56:33,251 - telethon.network.mtprotosender - INFO - Disconnection from 149.154.167.92:443/TcpFull complete!
2024-08-16 11:56:33,251 - telethon.network.mtprotosender - INFO - Not disconnecting (already have no connection)
2024-08-16 11:56:46,624 - telethon.client.updates - ERROR - Unhandled exception on get_url
Traceback (most recent call last):
  File "/usr/lib/python3.11/urllib/request.py", line 1348, in do_open
    h.request(req.get_method(), req.selector, req.data, headers,
  File "/usr/lib/python3.11/http/client.py", line 1303, in request
    self._send_request(method, url, body, headers, encode_chunked)
  File "/usr/lib/python3.11/http/client.py", line 1349, in _send_request
    self.endheaders(body, encode_chunked=encode_chunked)
  File "/usr/lib/python3.11/http/client.py", line 1298, in endheaders
    self._send_output(message_body, encode_chunked=encode_chunked)
  File "/usr/lib/python3.11/http/client.py", line 1058, in _send_output
    self.send(msg)
  File "/usr/lib/python3.11/http/client.py", line 996, in send
    self.connect()
  File "/usr/lib/python3.11/http/client.py", line 1475, in connect
    self.sock = self._context.wrap_socket(self.sock,
                ^^^^^^^^^^^^^^^^^^^^^^^^^^^^^^^^^^^^
  File "/usr/lib/python3.11/ssl.py", line 517, in wrap_socket
    return self.sslsocket_class._create(
           ^^^^^^^^^^^^^^^^^^^^^^^^^^^^^
  File "/usr/lib/python3.11/ssl.py", line 1104, in _create
    self.do_handshake()
  File "/usr/lib/python3.11/ssl.py", line 1382, in do_handshake
    self._sslobj.do_handshake()
ConnectionResetError: [Errno 104] Connection reset by peer

During handling of the above exception, another exception occurred:

Traceback (most recent call last):
  File "/home/mohammad/Documents/code/projects/PlusSaver/.venv/lib/python3.11/site-packages/telethon/client/updates.py", line 570, in _dispatch_update
    await callback(event)
  File "/home/mohammad/Documents/code/projects/PlusSaver/modules/handlers/handlers.py", line 414, in get_url
    await client.send_file(event.chat_id, file=video, caption=yt_client.youtube_client.channel_url)
                                                              ^^^^^^^^^^^^^^^^^^^^^^^^^^^^^^^^^^^^
  File "/home/mohammad/Documents/code/projects/PlusSaver/.venv/lib/python3.11/site-packages/pytube/__main__.py", line 432, in channel_url
    return f'https://www.youtube.com/channel/{self.channel_id}'
                                              ^^^^^^^^^^^^^^^
  File "/home/mohammad/Documents/code/projects/PlusSaver/.venv/lib/python3.11/site-packages/pytube/__main__.py", line 424, in channel_id
    return self.vid_info.get('videoDetails', {}).get('channelId', None)
           ^^^^^^^^^^^^^
  File "/home/mohammad/Documents/code/projects/PlusSaver/.venv/lib/python3.11/site-packages/pytube/__main__.py", line 246, in vid_info
    innertube_response = innertube.player(self.video_id)
                         ^^^^^^^^^^^^^^^^^^^^^^^^^^^^^^^
  File "/home/mohammad/Documents/code/projects/PlusSaver/.venv/lib/python3.11/site-packages/pytube/innertube.py", line 448, in player
    return self._call_api(endpoint, query, self.base_data)
           ^^^^^^^^^^^^^^^^^^^^^^^^^^^^^^^^^^^^^^^^^^^^^^^
  File "/home/mohammad/Documents/code/projects/PlusSaver/.venv/lib/python3.11/site-packages/pytube/innertube.py", line 390, in _call_api
    response = request._execute_request(
               ^^^^^^^^^^^^^^^^^^^^^^^^^
  File "/home/mohammad/Documents/code/projects/PlusSaver/.venv/lib/python3.11/site-packages/pytube/request.py", line 37, in _execute_request
    return urlopen(request, timeout=timeout)  # nosec
           ^^^^^^^^^^^^^^^^^^^^^^^^^^^^^^^^^
  File "/usr/lib/python3.11/urllib/request.py", line 216, in urlopen
    return opener.open(url, data, timeout)
           ^^^^^^^^^^^^^^^^^^^^^^^^^^^^^^^
  File "/usr/lib/python3.11/urllib/request.py", line 519, in open
    response = self._open(req, data)
               ^^^^^^^^^^^^^^^^^^^^^
  File "/usr/lib/python3.11/urllib/request.py", line 536, in _open
    result = self._call_chain(self.handle_open, protocol, protocol +
             ^^^^^^^^^^^^^^^^^^^^^^^^^^^^^^^^^^^^^^^^^^^^^^^^^^^^^^^
  File "/usr/lib/python3.11/urllib/request.py", line 496, in _call_chain
    result = func(*args)
             ^^^^^^^^^^^
  File "/usr/lib/python3.11/urllib/request.py", line 1391, in https_open
    return self.do_open(http.client.HTTPSConnection, req,
           ^^^^^^^^^^^^^^^^^^^^^^^^^^^^^^^^^^^^^^^^^^^^^^
  File "/usr/lib/python3.11/urllib/request.py", line 1351, in do_open
    raise URLError(err)
urllib.error.URLError: <urlopen error [Errno 104] Connection reset by peer>
2024-08-16 12:02:12,487 - telethon.network.mtprotosender - INFO - Disconnecting from 149.154.167.92:443/TcpFull...
2024-08-16 12:02:12,488 - telethon.network.mtprotosender - INFO - Disconnection from 149.154.167.92:443/TcpFull complete!
2024-08-16 12:02:12,489 - telethon.network.mtprotosender - INFO - Not disconnecting (already have no connection)
2024-08-16 12:02:29,237 - telethon.client.updates - ERROR - Unhandled exception on get_url
Traceback (most recent call last):
  File "/usr/lib/python3.11/urllib/request.py", line 1348, in do_open
    h.request(req.get_method(), req.selector, req.data, headers,
  File "/usr/lib/python3.11/http/client.py", line 1303, in request
    self._send_request(method, url, body, headers, encode_chunked)
  File "/usr/lib/python3.11/http/client.py", line 1349, in _send_request
    self.endheaders(body, encode_chunked=encode_chunked)
  File "/usr/lib/python3.11/http/client.py", line 1298, in endheaders
    self._send_output(message_body, encode_chunked=encode_chunked)
  File "/usr/lib/python3.11/http/client.py", line 1058, in _send_output
    self.send(msg)
  File "/usr/lib/python3.11/http/client.py", line 996, in send
    self.connect()
  File "/usr/lib/python3.11/http/client.py", line 1475, in connect
    self.sock = self._context.wrap_socket(self.sock,
                ^^^^^^^^^^^^^^^^^^^^^^^^^^^^^^^^^^^^
  File "/usr/lib/python3.11/ssl.py", line 517, in wrap_socket
    return self.sslsocket_class._create(
           ^^^^^^^^^^^^^^^^^^^^^^^^^^^^^
  File "/usr/lib/python3.11/ssl.py", line 1104, in _create
    self.do_handshake()
  File "/usr/lib/python3.11/ssl.py", line 1382, in do_handshake
    self._sslobj.do_handshake()
ConnectionResetError: [Errno 104] Connection reset by peer

During handling of the above exception, another exception occurred:

Traceback (most recent call last):
  File "/home/mohammad/Documents/code/projects/PlusSaver/.venv/lib/python3.11/site-packages/telethon/client/updates.py", line 570, in _dispatch_update
    await callback(event)
  File "/home/mohammad/Documents/code/projects/PlusSaver/modules/handlers/handlers.py", line 414, in get_url
    await client.send_file(event.chat_id, file=video, caption=yt_client.youtube_client.channel_url)
                                                              ^^^^^^^^^^^^^^^^^^^^^^^^^^^^^^^^^^^^
  File "/home/mohammad/Documents/code/projects/PlusSaver/.venv/lib/python3.11/site-packages/pytube/__main__.py", line 432, in channel_url
    return f'https://www.youtube.com/channel/{self.channel_id}'
                                              ^^^^^^^^^^^^^^^
  File "/home/mohammad/Documents/code/projects/PlusSaver/.venv/lib/python3.11/site-packages/pytube/__main__.py", line 424, in channel_id
    return self.vid_info.get('videoDetails', {}).get('channelId', None)
           ^^^^^^^^^^^^^
  File "/home/mohammad/Documents/code/projects/PlusSaver/.venv/lib/python3.11/site-packages/pytube/__main__.py", line 246, in vid_info
    innertube_response = innertube.player(self.video_id)
                         ^^^^^^^^^^^^^^^^^^^^^^^^^^^^^^^
  File "/home/mohammad/Documents/code/projects/PlusSaver/.venv/lib/python3.11/site-packages/pytube/innertube.py", line 448, in player
    return self._call_api(endpoint, query, self.base_data)
           ^^^^^^^^^^^^^^^^^^^^^^^^^^^^^^^^^^^^^^^^^^^^^^^
  File "/home/mohammad/Documents/code/projects/PlusSaver/.venv/lib/python3.11/site-packages/pytube/innertube.py", line 390, in _call_api
    response = request._execute_request(
               ^^^^^^^^^^^^^^^^^^^^^^^^^
  File "/home/mohammad/Documents/code/projects/PlusSaver/.venv/lib/python3.11/site-packages/pytube/request.py", line 37, in _execute_request
    return urlopen(request, timeout=timeout)  # nosec
           ^^^^^^^^^^^^^^^^^^^^^^^^^^^^^^^^^
  File "/usr/lib/python3.11/urllib/request.py", line 216, in urlopen
    return opener.open(url, data, timeout)
           ^^^^^^^^^^^^^^^^^^^^^^^^^^^^^^^
  File "/usr/lib/python3.11/urllib/request.py", line 519, in open
    response = self._open(req, data)
               ^^^^^^^^^^^^^^^^^^^^^
  File "/usr/lib/python3.11/urllib/request.py", line 536, in _open
    result = self._call_chain(self.handle_open, protocol, protocol +
             ^^^^^^^^^^^^^^^^^^^^^^^^^^^^^^^^^^^^^^^^^^^^^^^^^^^^^^^
  File "/usr/lib/python3.11/urllib/request.py", line 496, in _call_chain
    result = func(*args)
             ^^^^^^^^^^^
  File "/usr/lib/python3.11/urllib/request.py", line 1391, in https_open
    return self.do_open(http.client.HTTPSConnection, req,
           ^^^^^^^^^^^^^^^^^^^^^^^^^^^^^^^^^^^^^^^^^^^^^^
  File "/usr/lib/python3.11/urllib/request.py", line 1351, in do_open
    raise URLError(err)
urllib.error.URLError: <urlopen error [Errno 104] Connection reset by peer>
2024-08-16 12:06:04,568 - telethon.network.mtprotosender - INFO - Disconnecting from 149.154.167.92:443/TcpFull...
2024-08-16 12:06:04,569 - telethon.network.mtprotosender - INFO - Disconnection from 149.154.167.92:443/TcpFull complete!
2024-08-16 12:06:04,569 - telethon.network.mtprotosender - INFO - Not disconnecting (already have no connection)
2024-08-16 12:06:21,841 - telethon.client.updates - ERROR - Unhandled exception on get_url
Traceback (most recent call last):
  File "/usr/lib/python3.11/urllib/request.py", line 1348, in do_open
    h.request(req.get_method(), req.selector, req.data, headers,
  File "/usr/lib/python3.11/http/client.py", line 1303, in request
    self._send_request(method, url, body, headers, encode_chunked)
  File "/usr/lib/python3.11/http/client.py", line 1349, in _send_request
    self.endheaders(body, encode_chunked=encode_chunked)
  File "/usr/lib/python3.11/http/client.py", line 1298, in endheaders
    self._send_output(message_body, encode_chunked=encode_chunked)
  File "/usr/lib/python3.11/http/client.py", line 1058, in _send_output
    self.send(msg)
  File "/usr/lib/python3.11/http/client.py", line 996, in send
    self.connect()
  File "/usr/lib/python3.11/http/client.py", line 1475, in connect
    self.sock = self._context.wrap_socket(self.sock,
                ^^^^^^^^^^^^^^^^^^^^^^^^^^^^^^^^^^^^
  File "/usr/lib/python3.11/ssl.py", line 517, in wrap_socket
    return self.sslsocket_class._create(
           ^^^^^^^^^^^^^^^^^^^^^^^^^^^^^
  File "/usr/lib/python3.11/ssl.py", line 1104, in _create
    self.do_handshake()
  File "/usr/lib/python3.11/ssl.py", line 1382, in do_handshake
    self._sslobj.do_handshake()
ConnectionResetError: [Errno 104] Connection reset by peer

During handling of the above exception, another exception occurred:

Traceback (most recent call last):
  File "/home/mohammad/Documents/code/projects/PlusSaver/.venv/lib/python3.11/site-packages/telethon/client/updates.py", line 570, in _dispatch_update
    await callback(event)
  File "/home/mohammad/Documents/code/projects/PlusSaver/modules/handlers/handlers.py", line 414, in get_url
    await client.send_file(event.chat_id, file=video, caption=yt_client.youtube_client.channel_url)
                                                              ^^^^^^^^^^^^^^^^^^^^^^^^^^^^^^^^^^^^
  File "/home/mohammad/Documents/code/projects/PlusSaver/.venv/lib/python3.11/site-packages/pytube/__main__.py", line 432, in channel_url
    return f'https://www.youtube.com/channel/{self.channel_id}'
                                              ^^^^^^^^^^^^^^^
  File "/home/mohammad/Documents/code/projects/PlusSaver/.venv/lib/python3.11/site-packages/pytube/__main__.py", line 424, in channel_id
    return self.vid_info.get('videoDetails', {}).get('channelId', None)
           ^^^^^^^^^^^^^
  File "/home/mohammad/Documents/code/projects/PlusSaver/.venv/lib/python3.11/site-packages/pytube/__main__.py", line 246, in vid_info
    innertube_response = innertube.player(self.video_id)
                         ^^^^^^^^^^^^^^^^^^^^^^^^^^^^^^^
  File "/home/mohammad/Documents/code/projects/PlusSaver/.venv/lib/python3.11/site-packages/pytube/innertube.py", line 448, in player
    return self._call_api(endpoint, query, self.base_data)
           ^^^^^^^^^^^^^^^^^^^^^^^^^^^^^^^^^^^^^^^^^^^^^^^
  File "/home/mohammad/Documents/code/projects/PlusSaver/.venv/lib/python3.11/site-packages/pytube/innertube.py", line 390, in _call_api
    response = request._execute_request(
               ^^^^^^^^^^^^^^^^^^^^^^^^^
  File "/home/mohammad/Documents/code/projects/PlusSaver/.venv/lib/python3.11/site-packages/pytube/request.py", line 37, in _execute_request
    return urlopen(request, timeout=timeout)  # nosec
           ^^^^^^^^^^^^^^^^^^^^^^^^^^^^^^^^^
  File "/usr/lib/python3.11/urllib/request.py", line 216, in urlopen
    return opener.open(url, data, timeout)
           ^^^^^^^^^^^^^^^^^^^^^^^^^^^^^^^
  File "/usr/lib/python3.11/urllib/request.py", line 519, in open
    response = self._open(req, data)
               ^^^^^^^^^^^^^^^^^^^^^
  File "/usr/lib/python3.11/urllib/request.py", line 536, in _open
    result = self._call_chain(self.handle_open, protocol, protocol +
             ^^^^^^^^^^^^^^^^^^^^^^^^^^^^^^^^^^^^^^^^^^^^^^^^^^^^^^^
  File "/usr/lib/python3.11/urllib/request.py", line 496, in _call_chain
    result = func(*args)
             ^^^^^^^^^^^
  File "/usr/lib/python3.11/urllib/request.py", line 1391, in https_open
    return self.do_open(http.client.HTTPSConnection, req,
           ^^^^^^^^^^^^^^^^^^^^^^^^^^^^^^^^^^^^^^^^^^^^^^
  File "/usr/lib/python3.11/urllib/request.py", line 1351, in do_open
    raise URLError(err)
urllib.error.URLError: <urlopen error [Errno 104] Connection reset by peer>
2024-08-16 12:06:46,726 - telethon.network.connection.connection - WARNING - Server closed the connection: 0 bytes read on a total of 8 expected bytes
2024-08-16 12:06:46,726 - telethon.network.mtprotosender - INFO - Connection closed while receiving data: 0 bytes read on a total of 8 expected bytes
2024-08-16 12:06:46,727 - telethon.network.mtprotosender - INFO - Closing current connection to begin reconnect...
2024-08-16 12:06:46,727 - telethon.network.mtprotosender - INFO - Connecting to 149.154.167.92:443/TcpFull...
2024-08-16 12:06:46,737 - telethon.network.mtprotosender - INFO - Connection to 149.154.167.92:443/TcpFull complete!
2024-08-16 12:06:51,414 - telethon.network.mtprotosender - INFO - Disconnecting from 149.154.167.92:443/TcpFull...
2024-08-16 12:06:51,415 - telethon.network.mtprotosender - INFO - Disconnection from 149.154.167.92:443/TcpFull complete!
2024-08-16 12:06:51,415 - telethon.network.mtprotosender - INFO - Not disconnecting (already have no connection)
2024-08-16 12:07:04,831 - telethon.client.updates - ERROR - Unhandled exception on get_url
Traceback (most recent call last):
  File "/usr/lib/python3.11/urllib/request.py", line 1348, in do_open
    h.request(req.get_method(), req.selector, req.data, headers,
  File "/usr/lib/python3.11/http/client.py", line 1303, in request
    self._send_request(method, url, body, headers, encode_chunked)
  File "/usr/lib/python3.11/http/client.py", line 1349, in _send_request
    self.endheaders(body, encode_chunked=encode_chunked)
  File "/usr/lib/python3.11/http/client.py", line 1298, in endheaders
    self._send_output(message_body, encode_chunked=encode_chunked)
  File "/usr/lib/python3.11/http/client.py", line 1058, in _send_output
    self.send(msg)
  File "/usr/lib/python3.11/http/client.py", line 996, in send
    self.connect()
  File "/usr/lib/python3.11/http/client.py", line 1475, in connect
    self.sock = self._context.wrap_socket(self.sock,
                ^^^^^^^^^^^^^^^^^^^^^^^^^^^^^^^^^^^^
  File "/usr/lib/python3.11/ssl.py", line 517, in wrap_socket
    return self.sslsocket_class._create(
           ^^^^^^^^^^^^^^^^^^^^^^^^^^^^^
  File "/usr/lib/python3.11/ssl.py", line 1104, in _create
    self.do_handshake()
  File "/usr/lib/python3.11/ssl.py", line 1382, in do_handshake
    self._sslobj.do_handshake()
ConnectionResetError: [Errno 104] Connection reset by peer

During handling of the above exception, another exception occurred:

Traceback (most recent call last):
  File "/home/mohammad/Documents/code/projects/PlusSaver/.venv/lib/python3.11/site-packages/telethon/client/updates.py", line 570, in _dispatch_update
    await callback(event)
  File "/home/mohammad/Documents/code/projects/PlusSaver/modules/handlers/handlers.py", line 414, in get_url
    await client.send_file(event.chat_id, file=video, caption=yt_client.youtube_client.channel_url)
                                                              ^^^^^^^^^^^^^^^^^^^^^^^^^^^^^^^^^^^^
  File "/home/mohammad/Documents/code/projects/PlusSaver/.venv/lib/python3.11/site-packages/pytube/__main__.py", line 432, in channel_url
    return f'https://www.youtube.com/channel/{self.channel_id}'
                                              ^^^^^^^^^^^^^^^
  File "/home/mohammad/Documents/code/projects/PlusSaver/.venv/lib/python3.11/site-packages/pytube/__main__.py", line 424, in channel_id
    return self.vid_info.get('videoDetails', {}).get('channelId', None)
           ^^^^^^^^^^^^^
  File "/home/mohammad/Documents/code/projects/PlusSaver/.venv/lib/python3.11/site-packages/pytube/__main__.py", line 246, in vid_info
    innertube_response = innertube.player(self.video_id)
                         ^^^^^^^^^^^^^^^^^^^^^^^^^^^^^^^
  File "/home/mohammad/Documents/code/projects/PlusSaver/.venv/lib/python3.11/site-packages/pytube/innertube.py", line 448, in player
    return self._call_api(endpoint, query, self.base_data)
           ^^^^^^^^^^^^^^^^^^^^^^^^^^^^^^^^^^^^^^^^^^^^^^^
  File "/home/mohammad/Documents/code/projects/PlusSaver/.venv/lib/python3.11/site-packages/pytube/innertube.py", line 390, in _call_api
    response = request._execute_request(
               ^^^^^^^^^^^^^^^^^^^^^^^^^
  File "/home/mohammad/Documents/code/projects/PlusSaver/.venv/lib/python3.11/site-packages/pytube/request.py", line 37, in _execute_request
    return urlopen(request, timeout=timeout)  # nosec
           ^^^^^^^^^^^^^^^^^^^^^^^^^^^^^^^^^
  File "/usr/lib/python3.11/urllib/request.py", line 216, in urlopen
    return opener.open(url, data, timeout)
           ^^^^^^^^^^^^^^^^^^^^^^^^^^^^^^^
  File "/usr/lib/python3.11/urllib/request.py", line 519, in open
    response = self._open(req, data)
               ^^^^^^^^^^^^^^^^^^^^^
  File "/usr/lib/python3.11/urllib/request.py", line 536, in _open
    result = self._call_chain(self.handle_open, protocol, protocol +
             ^^^^^^^^^^^^^^^^^^^^^^^^^^^^^^^^^^^^^^^^^^^^^^^^^^^^^^^
  File "/usr/lib/python3.11/urllib/request.py", line 496, in _call_chain
    result = func(*args)
             ^^^^^^^^^^^
  File "/usr/lib/python3.11/urllib/request.py", line 1391, in https_open
    return self.do_open(http.client.HTTPSConnection, req,
           ^^^^^^^^^^^^^^^^^^^^^^^^^^^^^^^^^^^^^^^^^^^^^^
  File "/usr/lib/python3.11/urllib/request.py", line 1351, in do_open
    raise URLError(err)
urllib.error.URLError: <urlopen error [Errno 104] Connection reset by peer>
2024-08-16 12:07:36,314 - telethon.network.mtprotosender - INFO - Disconnecting from 149.154.167.92:443/TcpFull...
2024-08-16 12:07:36,316 - telethon.network.mtprotosender - INFO - Disconnection from 149.154.167.92:443/TcpFull complete!
2024-08-16 12:07:36,316 - telethon.network.mtprotosender - INFO - Not disconnecting (already have no connection)
2024-08-16 12:07:46,217 - telethon.client.updates - ERROR - Unhandled exception on get_url
Traceback (most recent call last):
  File "/usr/lib/python3.11/urllib/request.py", line 1348, in do_open
    h.request(req.get_method(), req.selector, req.data, headers,
  File "/usr/lib/python3.11/http/client.py", line 1303, in request
    self._send_request(method, url, body, headers, encode_chunked)
  File "/usr/lib/python3.11/http/client.py", line 1349, in _send_request
    self.endheaders(body, encode_chunked=encode_chunked)
  File "/usr/lib/python3.11/http/client.py", line 1298, in endheaders
    self._send_output(message_body, encode_chunked=encode_chunked)
  File "/usr/lib/python3.11/http/client.py", line 1058, in _send_output
    self.send(msg)
  File "/usr/lib/python3.11/http/client.py", line 996, in send
    self.connect()
  File "/usr/lib/python3.11/http/client.py", line 1475, in connect
    self.sock = self._context.wrap_socket(self.sock,
                ^^^^^^^^^^^^^^^^^^^^^^^^^^^^^^^^^^^^
  File "/usr/lib/python3.11/ssl.py", line 517, in wrap_socket
    return self.sslsocket_class._create(
           ^^^^^^^^^^^^^^^^^^^^^^^^^^^^^
  File "/usr/lib/python3.11/ssl.py", line 1104, in _create
    self.do_handshake()
  File "/usr/lib/python3.11/ssl.py", line 1382, in do_handshake
    self._sslobj.do_handshake()
ConnectionResetError: [Errno 104] Connection reset by peer

During handling of the above exception, another exception occurred:

Traceback (most recent call last):
  File "/home/mohammad/Documents/code/projects/PlusSaver/.venv/lib/python3.11/site-packages/telethon/client/updates.py", line 570, in _dispatch_update
    await callback(event)
  File "/home/mohammad/Documents/code/projects/PlusSaver/modules/handlers/handlers.py", line 414, in get_url
    await client.send_file(event.chat_id, file=video, caption=yt_client.youtube_client.channel_url)
                                                              ^^^^^^^^^^^^^^^^^^^^^^^^^^^^^^^^^^^^
  File "/home/mohammad/Documents/code/projects/PlusSaver/.venv/lib/python3.11/site-packages/pytube/__main__.py", line 432, in channel_url
    return f'https://www.youtube.com/channel/{self.channel_id}'
                                              ^^^^^^^^^^^^^^^
  File "/home/mohammad/Documents/code/projects/PlusSaver/.venv/lib/python3.11/site-packages/pytube/__main__.py", line 424, in channel_id
    return self.vid_info.get('videoDetails', {}).get('channelId', None)
           ^^^^^^^^^^^^^
  File "/home/mohammad/Documents/code/projects/PlusSaver/.venv/lib/python3.11/site-packages/pytube/__main__.py", line 246, in vid_info
    innertube_response = innertube.player(self.video_id)
                         ^^^^^^^^^^^^^^^^^^^^^^^^^^^^^^^
  File "/home/mohammad/Documents/code/projects/PlusSaver/.venv/lib/python3.11/site-packages/pytube/innertube.py", line 448, in player
    return self._call_api(endpoint, query, self.base_data)
           ^^^^^^^^^^^^^^^^^^^^^^^^^^^^^^^^^^^^^^^^^^^^^^^
  File "/home/mohammad/Documents/code/projects/PlusSaver/.venv/lib/python3.11/site-packages/pytube/innertube.py", line 390, in _call_api
    response = request._execute_request(
               ^^^^^^^^^^^^^^^^^^^^^^^^^
  File "/home/mohammad/Documents/code/projects/PlusSaver/.venv/lib/python3.11/site-packages/pytube/request.py", line 37, in _execute_request
    return urlopen(request, timeout=timeout)  # nosec
           ^^^^^^^^^^^^^^^^^^^^^^^^^^^^^^^^^
  File "/usr/lib/python3.11/urllib/request.py", line 216, in urlopen
    return opener.open(url, data, timeout)
           ^^^^^^^^^^^^^^^^^^^^^^^^^^^^^^^
  File "/usr/lib/python3.11/urllib/request.py", line 519, in open
    response = self._open(req, data)
               ^^^^^^^^^^^^^^^^^^^^^
  File "/usr/lib/python3.11/urllib/request.py", line 536, in _open
    result = self._call_chain(self.handle_open, protocol, protocol +
             ^^^^^^^^^^^^^^^^^^^^^^^^^^^^^^^^^^^^^^^^^^^^^^^^^^^^^^^
  File "/usr/lib/python3.11/urllib/request.py", line 496, in _call_chain
    result = func(*args)
             ^^^^^^^^^^^
  File "/usr/lib/python3.11/urllib/request.py", line 1391, in https_open
    return self.do_open(http.client.HTTPSConnection, req,
           ^^^^^^^^^^^^^^^^^^^^^^^^^^^^^^^^^^^^^^^^^^^^^^
  File "/usr/lib/python3.11/urllib/request.py", line 1351, in do_open
    raise URLError(err)
urllib.error.URLError: <urlopen error [Errno 104] Connection reset by peer>
2024-08-16 12:08:37,157 - telethon.client.updates - ERROR - Unhandled exception on get_url
Traceback (most recent call last):
  File "/usr/lib/python3.11/urllib/request.py", line 1348, in do_open
    h.request(req.get_method(), req.selector, req.data, headers,
  File "/usr/lib/python3.11/http/client.py", line 1303, in request
    self._send_request(method, url, body, headers, encode_chunked)
  File "/usr/lib/python3.11/http/client.py", line 1349, in _send_request
    self.endheaders(body, encode_chunked=encode_chunked)
  File "/usr/lib/python3.11/http/client.py", line 1298, in endheaders
    self._send_output(message_body, encode_chunked=encode_chunked)
  File "/usr/lib/python3.11/http/client.py", line 1058, in _send_output
    self.send(msg)
  File "/usr/lib/python3.11/http/client.py", line 996, in send
    self.connect()
  File "/usr/lib/python3.11/http/client.py", line 1475, in connect
    self.sock = self._context.wrap_socket(self.sock,
                ^^^^^^^^^^^^^^^^^^^^^^^^^^^^^^^^^^^^
  File "/usr/lib/python3.11/ssl.py", line 517, in wrap_socket
    return self.sslsocket_class._create(
           ^^^^^^^^^^^^^^^^^^^^^^^^^^^^^
  File "/usr/lib/python3.11/ssl.py", line 1104, in _create
    self.do_handshake()
  File "/usr/lib/python3.11/ssl.py", line 1382, in do_handshake
    self._sslobj.do_handshake()
ConnectionResetError: [Errno 104] Connection reset by peer

During handling of the above exception, another exception occurred:

Traceback (most recent call last):
  File "/home/mohammad/Documents/code/projects/PlusSaver/.venv/lib/python3.11/site-packages/telethon/client/updates.py", line 570, in _dispatch_update
    await callback(event)
  File "/home/mohammad/Documents/code/projects/PlusSaver/modules/handlers/handlers.py", line 414, in get_url
    await client.send_file(event.chat_id, file=video, caption=yt_client.youtube_client.channel_url)
                                                              ^^^^^^^^^^^^^^^^^^^^^^^^^^^^^^^^^^^^
  File "/home/mohammad/Documents/code/projects/PlusSaver/.venv/lib/python3.11/site-packages/pytube/__main__.py", line 432, in channel_url
    return f'https://www.youtube.com/channel/{self.channel_id}'
                                              ^^^^^^^^^^^^^^^
  File "/home/mohammad/Documents/code/projects/PlusSaver/.venv/lib/python3.11/site-packages/pytube/__main__.py", line 424, in channel_id
    return self.vid_info.get('videoDetails', {}).get('channelId', None)
           ^^^^^^^^^^^^^
  File "/home/mohammad/Documents/code/projects/PlusSaver/.venv/lib/python3.11/site-packages/pytube/__main__.py", line 246, in vid_info
    innertube_response = innertube.player(self.video_id)
                         ^^^^^^^^^^^^^^^^^^^^^^^^^^^^^^^
  File "/home/mohammad/Documents/code/projects/PlusSaver/.venv/lib/python3.11/site-packages/pytube/innertube.py", line 448, in player
    return self._call_api(endpoint, query, self.base_data)
           ^^^^^^^^^^^^^^^^^^^^^^^^^^^^^^^^^^^^^^^^^^^^^^^
  File "/home/mohammad/Documents/code/projects/PlusSaver/.venv/lib/python3.11/site-packages/pytube/innertube.py", line 390, in _call_api
    response = request._execute_request(
               ^^^^^^^^^^^^^^^^^^^^^^^^^
  File "/home/mohammad/Documents/code/projects/PlusSaver/.venv/lib/python3.11/site-packages/pytube/request.py", line 37, in _execute_request
    return urlopen(request, timeout=timeout)  # nosec
           ^^^^^^^^^^^^^^^^^^^^^^^^^^^^^^^^^
  File "/usr/lib/python3.11/urllib/request.py", line 216, in urlopen
    return opener.open(url, data, timeout)
           ^^^^^^^^^^^^^^^^^^^^^^^^^^^^^^^
  File "/usr/lib/python3.11/urllib/request.py", line 519, in open
    response = self._open(req, data)
               ^^^^^^^^^^^^^^^^^^^^^
  File "/usr/lib/python3.11/urllib/request.py", line 536, in _open
    result = self._call_chain(self.handle_open, protocol, protocol +
             ^^^^^^^^^^^^^^^^^^^^^^^^^^^^^^^^^^^^^^^^^^^^^^^^^^^^^^^
  File "/usr/lib/python3.11/urllib/request.py", line 496, in _call_chain
    result = func(*args)
             ^^^^^^^^^^^
  File "/usr/lib/python3.11/urllib/request.py", line 1391, in https_open
    return self.do_open(http.client.HTTPSConnection, req,
           ^^^^^^^^^^^^^^^^^^^^^^^^^^^^^^^^^^^^^^^^^^^^^^
  File "/usr/lib/python3.11/urllib/request.py", line 1351, in do_open
    raise URLError(err)
urllib.error.URLError: <urlopen error [Errno 104] Connection reset by peer>
2024-08-16 12:08:48,019 - telethon.network.mtprotosender - INFO - Disconnecting from 149.154.167.92:443/TcpFull...
2024-08-16 12:08:48,019 - telethon.network.mtprotosender - INFO - Disconnection from 149.154.167.92:443/TcpFull complete!
2024-08-16 12:08:48,020 - telethon.network.mtprotosender - INFO - Not disconnecting (already have no connection)
2024-08-16 12:08:57,449 - telethon.client.updates - ERROR - Unhandled exception on get_url
Traceback (most recent call last):
  File "/usr/lib/python3.11/urllib/request.py", line 1348, in do_open
    h.request(req.get_method(), req.selector, req.data, headers,
  File "/usr/lib/python3.11/http/client.py", line 1303, in request
    self._send_request(method, url, body, headers, encode_chunked)
  File "/usr/lib/python3.11/http/client.py", line 1349, in _send_request
    self.endheaders(body, encode_chunked=encode_chunked)
  File "/usr/lib/python3.11/http/client.py", line 1298, in endheaders
    self._send_output(message_body, encode_chunked=encode_chunked)
  File "/usr/lib/python3.11/http/client.py", line 1058, in _send_output
    self.send(msg)
  File "/usr/lib/python3.11/http/client.py", line 996, in send
    self.connect()
  File "/usr/lib/python3.11/http/client.py", line 1475, in connect
    self.sock = self._context.wrap_socket(self.sock,
                ^^^^^^^^^^^^^^^^^^^^^^^^^^^^^^^^^^^^
  File "/usr/lib/python3.11/ssl.py", line 517, in wrap_socket
    return self.sslsocket_class._create(
           ^^^^^^^^^^^^^^^^^^^^^^^^^^^^^
  File "/usr/lib/python3.11/ssl.py", line 1104, in _create
    self.do_handshake()
  File "/usr/lib/python3.11/ssl.py", line 1382, in do_handshake
    self._sslobj.do_handshake()
ConnectionResetError: [Errno 104] Connection reset by peer

During handling of the above exception, another exception occurred:

Traceback (most recent call last):
  File "/home/mohammad/Documents/code/projects/PlusSaver/.venv/lib/python3.11/site-packages/telethon/client/updates.py", line 570, in _dispatch_update
    await callback(event)
  File "/home/mohammad/Documents/code/projects/PlusSaver/modules/handlers/handlers.py", line 414, in get_url
    await client.send_file(event.chat_id, file=video, caption=yt_client.youtube_client.channel_url)
                                                              ^^^^^^^^^^^^^^^^^^^^^^^^^^^^^^^^^^^^
  File "/home/mohammad/Documents/code/projects/PlusSaver/.venv/lib/python3.11/site-packages/pytube/__main__.py", line 432, in channel_url
    return f'https://www.youtube.com/channel/{self.channel_id}'
                                              ^^^^^^^^^^^^^^^
  File "/home/mohammad/Documents/code/projects/PlusSaver/.venv/lib/python3.11/site-packages/pytube/__main__.py", line 424, in channel_id
    return self.vid_info.get('videoDetails', {}).get('channelId', None)
           ^^^^^^^^^^^^^
  File "/home/mohammad/Documents/code/projects/PlusSaver/.venv/lib/python3.11/site-packages/pytube/__main__.py", line 246, in vid_info
    innertube_response = innertube.player(self.video_id)
                         ^^^^^^^^^^^^^^^^^^^^^^^^^^^^^^^
  File "/home/mohammad/Documents/code/projects/PlusSaver/.venv/lib/python3.11/site-packages/pytube/innertube.py", line 448, in player
    return self._call_api(endpoint, query, self.base_data)
           ^^^^^^^^^^^^^^^^^^^^^^^^^^^^^^^^^^^^^^^^^^^^^^^
  File "/home/mohammad/Documents/code/projects/PlusSaver/.venv/lib/python3.11/site-packages/pytube/innertube.py", line 390, in _call_api
    response = request._execute_request(
               ^^^^^^^^^^^^^^^^^^^^^^^^^
  File "/home/mohammad/Documents/code/projects/PlusSaver/.venv/lib/python3.11/site-packages/pytube/request.py", line 37, in _execute_request
    return urlopen(request, timeout=timeout)  # nosec
           ^^^^^^^^^^^^^^^^^^^^^^^^^^^^^^^^^
  File "/usr/lib/python3.11/urllib/request.py", line 216, in urlopen
    return opener.open(url, data, timeout)
           ^^^^^^^^^^^^^^^^^^^^^^^^^^^^^^^
  File "/usr/lib/python3.11/urllib/request.py", line 519, in open
    response = self._open(req, data)
               ^^^^^^^^^^^^^^^^^^^^^
  File "/usr/lib/python3.11/urllib/request.py", line 536, in _open
    result = self._call_chain(self.handle_open, protocol, protocol +
             ^^^^^^^^^^^^^^^^^^^^^^^^^^^^^^^^^^^^^^^^^^^^^^^^^^^^^^^
  File "/usr/lib/python3.11/urllib/request.py", line 496, in _call_chain
    result = func(*args)
             ^^^^^^^^^^^
  File "/usr/lib/python3.11/urllib/request.py", line 1391, in https_open
    return self.do_open(http.client.HTTPSConnection, req,
           ^^^^^^^^^^^^^^^^^^^^^^^^^^^^^^^^^^^^^^^^^^^^^^
  File "/usr/lib/python3.11/urllib/request.py", line 1351, in do_open
    raise URLError(err)
urllib.error.URLError: <urlopen error [Errno 104] Connection reset by peer>
2024-08-16 12:09:07,983 - telethon.client.updates - ERROR - Unhandled exception on get_url
Traceback (most recent call last):
  File "/usr/lib/python3.11/urllib/request.py", line 1348, in do_open
    h.request(req.get_method(), req.selector, req.data, headers,
  File "/usr/lib/python3.11/http/client.py", line 1303, in request
    self._send_request(method, url, body, headers, encode_chunked)
  File "/usr/lib/python3.11/http/client.py", line 1349, in _send_request
    self.endheaders(body, encode_chunked=encode_chunked)
  File "/usr/lib/python3.11/http/client.py", line 1298, in endheaders
    self._send_output(message_body, encode_chunked=encode_chunked)
  File "/usr/lib/python3.11/http/client.py", line 1058, in _send_output
    self.send(msg)
  File "/usr/lib/python3.11/http/client.py", line 996, in send
    self.connect()
  File "/usr/lib/python3.11/http/client.py", line 1475, in connect
    self.sock = self._context.wrap_socket(self.sock,
                ^^^^^^^^^^^^^^^^^^^^^^^^^^^^^^^^^^^^
  File "/usr/lib/python3.11/ssl.py", line 517, in wrap_socket
    return self.sslsocket_class._create(
           ^^^^^^^^^^^^^^^^^^^^^^^^^^^^^
  File "/usr/lib/python3.11/ssl.py", line 1104, in _create
    self.do_handshake()
  File "/usr/lib/python3.11/ssl.py", line 1382, in do_handshake
    self._sslobj.do_handshake()
ConnectionResetError: [Errno 104] Connection reset by peer

During handling of the above exception, another exception occurred:

Traceback (most recent call last):
  File "/home/mohammad/Documents/code/projects/PlusSaver/.venv/lib/python3.11/site-packages/telethon/client/updates.py", line 570, in _dispatch_update
    await callback(event)
  File "/home/mohammad/Documents/code/projects/PlusSaver/modules/handlers/handlers.py", line 414, in get_url
    await client.send_file(event.chat_id, file=video, caption=yt_client.youtube_client.channel_url)
                                                              ^^^^^^^^^^^^^^^^^^^^^^^^^^^^^^^^^^^^
  File "/home/mohammad/Documents/code/projects/PlusSaver/.venv/lib/python3.11/site-packages/pytube/__main__.py", line 432, in channel_url
    return f'https://www.youtube.com/channel/{self.channel_id}'
                                              ^^^^^^^^^^^^^^^
  File "/home/mohammad/Documents/code/projects/PlusSaver/.venv/lib/python3.11/site-packages/pytube/__main__.py", line 424, in channel_id
    return self.vid_info.get('videoDetails', {}).get('channelId', None)
           ^^^^^^^^^^^^^
  File "/home/mohammad/Documents/code/projects/PlusSaver/.venv/lib/python3.11/site-packages/pytube/__main__.py", line 246, in vid_info
    innertube_response = innertube.player(self.video_id)
                         ^^^^^^^^^^^^^^^^^^^^^^^^^^^^^^^
  File "/home/mohammad/Documents/code/projects/PlusSaver/.venv/lib/python3.11/site-packages/pytube/innertube.py", line 448, in player
    return self._call_api(endpoint, query, self.base_data)
           ^^^^^^^^^^^^^^^^^^^^^^^^^^^^^^^^^^^^^^^^^^^^^^^
  File "/home/mohammad/Documents/code/projects/PlusSaver/.venv/lib/python3.11/site-packages/pytube/innertube.py", line 390, in _call_api
    response = request._execute_request(
               ^^^^^^^^^^^^^^^^^^^^^^^^^
  File "/home/mohammad/Documents/code/projects/PlusSaver/.venv/lib/python3.11/site-packages/pytube/request.py", line 37, in _execute_request
    return urlopen(request, timeout=timeout)  # nosec
           ^^^^^^^^^^^^^^^^^^^^^^^^^^^^^^^^^
  File "/usr/lib/python3.11/urllib/request.py", line 216, in urlopen
    return opener.open(url, data, timeout)
           ^^^^^^^^^^^^^^^^^^^^^^^^^^^^^^^
  File "/usr/lib/python3.11/urllib/request.py", line 519, in open
    response = self._open(req, data)
               ^^^^^^^^^^^^^^^^^^^^^
  File "/usr/lib/python3.11/urllib/request.py", line 536, in _open
    result = self._call_chain(self.handle_open, protocol, protocol +
             ^^^^^^^^^^^^^^^^^^^^^^^^^^^^^^^^^^^^^^^^^^^^^^^^^^^^^^^
  File "/usr/lib/python3.11/urllib/request.py", line 496, in _call_chain
    result = func(*args)
             ^^^^^^^^^^^
  File "/usr/lib/python3.11/urllib/request.py", line 1391, in https_open
    return self.do_open(http.client.HTTPSConnection, req,
           ^^^^^^^^^^^^^^^^^^^^^^^^^^^^^^^^^^^^^^^^^^^^^^
  File "/usr/lib/python3.11/urllib/request.py", line 1351, in do_open
    raise URLError(err)
urllib.error.URLError: <urlopen error [Errno 104] Connection reset by peer>
2024-08-16 12:13:03,640 - telethon.client.updates - ERROR - Unhandled exception on get_url
Traceback (most recent call last):
  File "/usr/lib/python3.11/urllib/request.py", line 1348, in do_open
    h.request(req.get_method(), req.selector, req.data, headers,
  File "/usr/lib/python3.11/http/client.py", line 1303, in request
    self._send_request(method, url, body, headers, encode_chunked)
  File "/usr/lib/python3.11/http/client.py", line 1349, in _send_request
    self.endheaders(body, encode_chunked=encode_chunked)
  File "/usr/lib/python3.11/http/client.py", line 1298, in endheaders
    self._send_output(message_body, encode_chunked=encode_chunked)
  File "/usr/lib/python3.11/http/client.py", line 1058, in _send_output
    self.send(msg)
  File "/usr/lib/python3.11/http/client.py", line 996, in send
    self.connect()
  File "/usr/lib/python3.11/http/client.py", line 1475, in connect
    self.sock = self._context.wrap_socket(self.sock,
                ^^^^^^^^^^^^^^^^^^^^^^^^^^^^^^^^^^^^
  File "/usr/lib/python3.11/ssl.py", line 517, in wrap_socket
    return self.sslsocket_class._create(
           ^^^^^^^^^^^^^^^^^^^^^^^^^^^^^
  File "/usr/lib/python3.11/ssl.py", line 1104, in _create
    self.do_handshake()
  File "/usr/lib/python3.11/ssl.py", line 1382, in do_handshake
    self._sslobj.do_handshake()
ConnectionResetError: [Errno 104] Connection reset by peer

During handling of the above exception, another exception occurred:

Traceback (most recent call last):
  File "/home/mohammad/Documents/code/projects/PlusSaver/.venv/lib/python3.11/site-packages/telethon/client/updates.py", line 570, in _dispatch_update
    await callback(event)
  File "/home/mohammad/Documents/code/projects/PlusSaver/modules/handlers/handlers.py", line 414, in get_url
    await client.send_file(event.chat_id, file=video, caption=yt_client.youtube_client.channel_url)
                                                              ^^^^^^^^^^^^^^^^^^^^^^^^^^^^^^^^^^^^
  File "/home/mohammad/Documents/code/projects/PlusSaver/.venv/lib/python3.11/site-packages/pytube/__main__.py", line 432, in channel_url
    return f'https://www.youtube.com/channel/{self.channel_id}'
                                              ^^^^^^^^^^^^^^^
  File "/home/mohammad/Documents/code/projects/PlusSaver/.venv/lib/python3.11/site-packages/pytube/__main__.py", line 424, in channel_id
    return self.vid_info.get('videoDetails', {}).get('channelId', None)
           ^^^^^^^^^^^^^
  File "/home/mohammad/Documents/code/projects/PlusSaver/.venv/lib/python3.11/site-packages/pytube/__main__.py", line 246, in vid_info
    innertube_response = innertube.player(self.video_id)
                         ^^^^^^^^^^^^^^^^^^^^^^^^^^^^^^^
  File "/home/mohammad/Documents/code/projects/PlusSaver/.venv/lib/python3.11/site-packages/pytube/innertube.py", line 448, in player
    return self._call_api(endpoint, query, self.base_data)
           ^^^^^^^^^^^^^^^^^^^^^^^^^^^^^^^^^^^^^^^^^^^^^^^
  File "/home/mohammad/Documents/code/projects/PlusSaver/.venv/lib/python3.11/site-packages/pytube/innertube.py", line 390, in _call_api
    response = request._execute_request(
               ^^^^^^^^^^^^^^^^^^^^^^^^^
  File "/home/mohammad/Documents/code/projects/PlusSaver/.venv/lib/python3.11/site-packages/pytube/request.py", line 37, in _execute_request
    return urlopen(request, timeout=timeout)  # nosec
           ^^^^^^^^^^^^^^^^^^^^^^^^^^^^^^^^^
  File "/usr/lib/python3.11/urllib/request.py", line 216, in urlopen
    return opener.open(url, data, timeout)
           ^^^^^^^^^^^^^^^^^^^^^^^^^^^^^^^
  File "/usr/lib/python3.11/urllib/request.py", line 519, in open
    response = self._open(req, data)
               ^^^^^^^^^^^^^^^^^^^^^
  File "/usr/lib/python3.11/urllib/request.py", line 536, in _open
    result = self._call_chain(self.handle_open, protocol, protocol +
             ^^^^^^^^^^^^^^^^^^^^^^^^^^^^^^^^^^^^^^^^^^^^^^^^^^^^^^^
  File "/usr/lib/python3.11/urllib/request.py", line 496, in _call_chain
    result = func(*args)
             ^^^^^^^^^^^
  File "/usr/lib/python3.11/urllib/request.py", line 1391, in https_open
    return self.do_open(http.client.HTTPSConnection, req,
           ^^^^^^^^^^^^^^^^^^^^^^^^^^^^^^^^^^^^^^^^^^^^^^
  File "/usr/lib/python3.11/urllib/request.py", line 1351, in do_open
    raise URLError(err)
urllib.error.URLError: <urlopen error [Errno 104] Connection reset by peer>
2024-08-16 12:20:20,097 - telethon.network.mtprotosender - INFO - Disconnecting from 149.154.167.92:443/TcpFull...
2024-08-16 12:20:20,098 - telethon.network.mtprotosender - INFO - Disconnection from 149.154.167.92:443/TcpFull complete!
2024-08-16 12:20:20,099 - telethon.network.mtprotosender - INFO - Not disconnecting (already have no connection)
2024-08-16 12:30:31,264 - telethon.client.updates - ERROR - Unhandled exception on get_url
Traceback (most recent call last):
  File "/home/mohammad/Documents/code/projects/PlusSaver/.venv/lib/python3.11/site-packages/telethon/client/updates.py", line 570, in _dispatch_update
    await callback(event)
  File "/home/mohammad/Documents/code/projects/PlusSaver/modules/handlers/handlers.py", line 419, in get_url
    music = soundcloud_client.download_music()
            ^^^^^^^^^^^^^^^^^^^^^^^^^^^^^^^^^^
  File "/home/mohammad/Documents/code/projects/PlusSaver/modules/downloaders/soundcloud.py", line 24, in download_music
    with open(filename, 'wb+') as file:
         ^^^^^^^^^^^^^^^^^^^^^
FileNotFoundError: [Errno 2] No such file or directory: './download/soundcloud/music/Aphelion.mp3'
2024-08-16 12:31:16,586 - telethon.client.updates - ERROR - Unhandled exception on get_url
Traceback (most recent call last):
  File "/home/mohammad/Documents/code/projects/PlusSaver/.venv/lib/python3.11/site-packages/telethon/client/updates.py", line 570, in _dispatch_update
    await callback(event)
  File "/home/mohammad/Documents/code/projects/PlusSaver/modules/handlers/handlers.py", line 419, in get_url
    soundcloud_client = SoundCloud(event.message.message)
            ^^^^^^^^^^^^^^^^^^^^^^^^^^^^^^^^^^
  File "/home/mohammad/Documents/code/projects/PlusSaver/modules/downloaders/soundcloud.py", line 24, in download_music
    with open(filename, 'wb+') as file:
         ^^^^^^^^^^^^^^^^^^^^^
FileNotFoundError: [Errno 2] No such file or directory: './download/soundcloud/music/Aphelion.mp3'
2024-08-16 12:33:03,680 - telethon.client.uploads - INFO - Uploading file of 2437847 bytes in 19 chunks of 131072
2024-08-16 12:33:49,704 - telethon.network.mtprotosender - INFO - Disconnecting from 149.154.167.92:443/TcpFull...
2024-08-16 12:33:49,705 - telethon.network.mtprotosender - INFO - Disconnection from 149.154.167.92:443/TcpFull complete!
2024-08-16 12:33:49,706 - telethon.network.mtprotosender - INFO - Not disconnecting (already have no connection)
2024-08-16 12:34:37,699 - telethon.client.updates - INFO - Got difference for account updates
2024-08-16 12:35:19,446 - telethon.client.updates - INFO - Got difference for channel 1651163544 updates
2024-08-16 12:35:33,455 - telethon.client.uploads - INFO - Uploading file of 2437847 bytes in 19 chunks of 131072
2024-08-16 12:37:43,337 - telethon.client.updates - ERROR - Unhandled exception on get_url
Traceback (most recent call last):
  File "/home/mohammad/Documents/code/projects/PlusSaver/.venv/lib/python3.11/site-packages/telethon/client/updates.py", line 570, in _dispatch_update
    await callback(event)
  File "/home/mohammad/Documents/code/projects/PlusSaver/modules/handlers/handlers.py", line 420, in get_url
    music = soundcloud_client.download_music()
            ^^^^^^^^^^^^^^^^^^^^^^^^^^^^^^^^^^
  File "/home/mohammad/Documents/code/projects/PlusSaver/modules/downloaders/soundcloud.py", line 18, in download_music
    self.music = self.soundcloud_client.resolve(self.url)
                 ^^^^^^^^^^^^^^^^^^^^^^^^^^^^^^^^^^^^^^^^
  File "/home/mohammad/Documents/code/projects/PlusSaver/.venv/lib/python3.11/site-packages/sclib/sync.py", line 77, in resolve
    self.get_credentials()
  File "/home/mohammad/Documents/code/projects/PlusSaver/.venv/lib/python3.11/site-packages/sclib/sync.py", line 66, in get_credentials
    page_text = get_page(url)
                ^^^^^^^^^^^^^
  File "/home/mohammad/Documents/code/projects/PlusSaver/.venv/lib/python3.11/site-packages/sclib/sync.py", line 27, in get_page
    return get_url(url).decode('utf-8')
           ^^^^^^^^^^^^
  File "/home/mohammad/Documents/code/projects/PlusSaver/.venv/lib/python3.11/site-packages/sclib/sync.py", line 22, in get_url
    text = client.read()
           ^^^^^^^^^^^^^
  File "/usr/lib/python3.11/http/client.py", line 489, in read
    s = self._safe_read(self.length)
        ^^^^^^^^^^^^^^^^^^^^^^^^^^^^
  File "/usr/lib/python3.11/http/client.py", line 640, in _safe_read
    raise IncompleteRead(data, amt-len(data))
http.client.IncompleteRead: IncompleteRead(23842 bytes read, 11621 more expected)
2024-08-16 12:39:08,166 - telethon.client.uploads - INFO - Uploading file of 2033117 bytes in 16 chunks of 131072
2024-08-16 12:40:13,627 - telethon.network.mtprotosender - INFO - Disconnecting from 149.154.167.92:443/TcpFull...
2024-08-16 12:40:13,628 - telethon.network.mtprotosender - INFO - Disconnection from 149.154.167.92:443/TcpFull complete!
2024-08-16 12:40:13,628 - telethon.network.mtprotosender - INFO - Not disconnecting (already have no connection)
2024-08-16 12:40:49,514 - telethon.client.uploads - INFO - Uploading file of 2033117 bytes in 16 chunks of 131072
2024-08-16 12:40:57,448 - telethon.client.updates - INFO - Got difference for account updates
2024-08-16 12:40:57,657 - telethon.client.updates - INFO - Got difference for channel 1651163544 updates
2024-08-16 13:05:09,780 - telethon.client.uploads - INFO - Uploading file of 2853367 bytes in 22 chunks of 131072
2024-08-16 13:05:19,094 - telethon.client.updates - INFO - Got difference for account updates
2024-08-16 13:08:50,374 - telethon.network.mtprotosender - INFO - Disconnecting from 149.154.167.92:443/TcpFull...
2024-08-16 13:08:50,375 - telethon.network.mtprotosender - INFO - Disconnection from 149.154.167.92:443/TcpFull complete!
2024-08-16 13:08:50,376 - telethon.network.mtprotosender - INFO - Not disconnecting (already have no connection)
2024-08-16 13:12:29,080 - telethon.client.uploads - INFO - Uploading file of 2903023 bytes in 23 chunks of 131072
2024-08-16 13:12:52,120 - telethon.client.updates - ERROR - Unhandled exception on get_url
Traceback (most recent call last):
  File "/home/mohammad/Documents/code/projects/PlusSaver/.venv/lib/python3.11/site-packages/telethon/client/updates.py", line 570, in _dispatch_update
    await callback(event)
  File "/home/mohammad/Documents/code/projects/PlusSaver/modules/handlers/handlers.py", line 426, in get_url
    os.remove(music)
TypeError: remove: path should be string, bytes or os.PathLike, not MediaDownloaded
