2024-08-17 11:28:50,208 - telethon.network.mtprotosender - INFO - Disconnecting from 149.154.167.92:443/TcpFull...
2024-08-17 11:28:50,209 - telethon.network.mtprotosender - INFO - Disconnection from 149.154.167.92:443/TcpFull complete!
2024-08-17 11:28:50,209 - telethon.network.mtprotosender - INFO - Not disconnecting (already have no connection)
2024-08-17 12:27:28,070 - telethon.network.mtprotosender - INFO - Disconnecting from 149.154.167.92:443/TcpFull...
2024-08-17 12:27:28,072 - telethon.network.mtprotosender - INFO - Disconnection from 149.154.167.92:443/TcpFull complete!
2024-08-17 12:27:28,072 - telethon.network.mtprotosender - INFO - Not disconnecting (already have no connection)
2024-08-17 12:28:07,991 - telethon.client.updates - ERROR - Unhandled exception on get_url
Traceback (most recent call last):
  File "/home/mohammad/Documents/code/projects/PlusSaver/.venv/lib/python3.11/site-packages/urllib3/connectionpool.py", line 789, in urlopen
    response = self._make_request(
               ^^^^^^^^^^^^^^^^^^^
  File "/home/mohammad/Documents/code/projects/PlusSaver/.venv/lib/python3.11/site-packages/urllib3/connectionpool.py", line 490, in _make_request
    raise new_e
  File "/home/mohammad/Documents/code/projects/PlusSaver/.venv/lib/python3.11/site-packages/urllib3/connectionpool.py", line 466, in _make_request
    self._validate_conn(conn)
  File "/home/mohammad/Documents/code/projects/PlusSaver/.venv/lib/python3.11/site-packages/urllib3/connectionpool.py", line 1095, in _validate_conn
    conn.connect()
  File "/home/mohammad/Documents/code/projects/PlusSaver/.venv/lib/python3.11/site-packages/urllib3/connection.py", line 652, in connect
    sock_and_verified = _ssl_wrap_socket_and_match_hostname(
                        ^^^^^^^^^^^^^^^^^^^^^^^^^^^^^^^^^^^^
  File "/home/mohammad/Documents/code/projects/PlusSaver/.venv/lib/python3.11/site-packages/urllib3/connection.py", line 805, in _ssl_wrap_socket_and_match_hostname
    ssl_sock = ssl_wrap_socket(
               ^^^^^^^^^^^^^^^^
  File "/home/mohammad/Documents/code/projects/PlusSaver/.venv/lib/python3.11/site-packages/urllib3/util/ssl_.py", line 465, in ssl_wrap_socket
    ssl_sock = _ssl_wrap_socket_impl(sock, context, tls_in_tls, server_hostname)
               ^^^^^^^^^^^^^^^^^^^^^^^^^^^^^^^^^^^^^^^^^^^^^^^^^^^^^^^^^^^^^^^^^
  File "/home/mohammad/Documents/code/projects/PlusSaver/.venv/lib/python3.11/site-packages/urllib3/util/ssl_.py", line 509, in _ssl_wrap_socket_impl
    return ssl_context.wrap_socket(sock, server_hostname=server_hostname)
           ^^^^^^^^^^^^^^^^^^^^^^^^^^^^^^^^^^^^^^^^^^^^^^^^^^^^^^^^^^^^^^
  File "/usr/lib/python3.11/ssl.py", line 517, in wrap_socket
    return self.sslsocket_class._create(
           ^^^^^^^^^^^^^^^^^^^^^^^^^^^^^
  File "/usr/lib/python3.11/ssl.py", line 1104, in _create
    self.do_handshake()
  File "/usr/lib/python3.11/ssl.py", line 1382, in do_handshake
    self._sslobj.do_handshake()
ConnectionResetError: [Errno 104] Connection reset by peer

During handling of the above exception, another exception occurred:

Traceback (most recent call last):
  File "/home/mohammad/Documents/code/projects/PlusSaver/.venv/lib/python3.11/site-packages/requests/adapters.py", line 667, in send
    resp = conn.urlopen(
           ^^^^^^^^^^^^^
  File "/home/mohammad/Documents/code/projects/PlusSaver/.venv/lib/python3.11/site-packages/urllib3/connectionpool.py", line 843, in urlopen
    retries = retries.increment(
              ^^^^^^^^^^^^^^^^^^
  File "/home/mohammad/Documents/code/projects/PlusSaver/.venv/lib/python3.11/site-packages/urllib3/util/retry.py", line 474, in increment
    raise reraise(type(error), error, _stacktrace)
          ^^^^^^^^^^^^^^^^^^^^^^^^^^^^^^^^^^^^^^^^
  File "/home/mohammad/Documents/code/projects/PlusSaver/.venv/lib/python3.11/site-packages/urllib3/util/util.py", line 38, in reraise
    raise value.with_traceback(tb)
  File "/home/mohammad/Documents/code/projects/PlusSaver/.venv/lib/python3.11/site-packages/urllib3/connectionpool.py", line 789, in urlopen
    response = self._make_request(
               ^^^^^^^^^^^^^^^^^^^
  File "/home/mohammad/Documents/code/projects/PlusSaver/.venv/lib/python3.11/site-packages/urllib3/connectionpool.py", line 490, in _make_request
    raise new_e
  File "/home/mohammad/Documents/code/projects/PlusSaver/.venv/lib/python3.11/site-packages/urllib3/connectionpool.py", line 466, in _make_request
    self._validate_conn(conn)
  File "/home/mohammad/Documents/code/projects/PlusSaver/.venv/lib/python3.11/site-packages/urllib3/connectionpool.py", line 1095, in _validate_conn
    conn.connect()
  File "/home/mohammad/Documents/code/projects/PlusSaver/.venv/lib/python3.11/site-packages/urllib3/connection.py", line 652, in connect
    sock_and_verified = _ssl_wrap_socket_and_match_hostname(
                        ^^^^^^^^^^^^^^^^^^^^^^^^^^^^^^^^^^^^
  File "/home/mohammad/Documents/code/projects/PlusSaver/.venv/lib/python3.11/site-packages/urllib3/connection.py", line 805, in _ssl_wrap_socket_and_match_hostname
    ssl_sock = ssl_wrap_socket(
               ^^^^^^^^^^^^^^^^
  File "/home/mohammad/Documents/code/projects/PlusSaver/.venv/lib/python3.11/site-packages/urllib3/util/ssl_.py", line 465, in ssl_wrap_socket
    ssl_sock = _ssl_wrap_socket_impl(sock, context, tls_in_tls, server_hostname)
               ^^^^^^^^^^^^^^^^^^^^^^^^^^^^^^^^^^^^^^^^^^^^^^^^^^^^^^^^^^^^^^^^^
  File "/home/mohammad/Documents/code/projects/PlusSaver/.venv/lib/python3.11/site-packages/urllib3/util/ssl_.py", line 509, in _ssl_wrap_socket_impl
    return ssl_context.wrap_socket(sock, server_hostname=server_hostname)
           ^^^^^^^^^^^^^^^^^^^^^^^^^^^^^^^^^^^^^^^^^^^^^^^^^^^^^^^^^^^^^^
  File "/usr/lib/python3.11/ssl.py", line 517, in wrap_socket
    return self.sslsocket_class._create(
           ^^^^^^^^^^^^^^^^^^^^^^^^^^^^^
  File "/usr/lib/python3.11/ssl.py", line 1104, in _create
    self.do_handshake()
  File "/usr/lib/python3.11/ssl.py", line 1382, in do_handshake
    self._sslobj.do_handshake()
urllib3.exceptions.ProtocolError: ('Connection aborted.', ConnectionResetError(104, 'Connection reset by peer'))

During handling of the above exception, another exception occurred:

Traceback (most recent call last):
  File "/home/mohammad/Documents/code/projects/PlusSaver/.venv/lib/python3.11/site-packages/instaloader/instaloadercontext.py", line 425, in get_json
    resp = sess.get('https://{0}/{1}'.format(host, path), params=params, allow_redirects=False)
           ^^^^^^^^^^^^^^^^^^^^^^^^^^^^^^^^^^^^^^^^^^^^^^^^^^^^^^^^^^^^^^^^^^^^^^^^^^^^^^^^^^^^
  File "/home/mohammad/Documents/code/projects/PlusSaver/.venv/lib/python3.11/site-packages/requests/sessions.py", line 602, in get
    return self.request("GET", url, **kwargs)
           ^^^^^^^^^^^^^^^^^^^^^^^^^^^^^^^^^^
  File "/home/mohammad/Documents/code/projects/PlusSaver/.venv/lib/python3.11/site-packages/requests/sessions.py", line 589, in request
    resp = self.send(prep, **send_kwargs)
           ^^^^^^^^^^^^^^^^^^^^^^^^^^^^^^
  File "/home/mohammad/Documents/code/projects/PlusSaver/.venv/lib/python3.11/site-packages/requests/sessions.py", line 703, in send
    r = adapter.send(request, **kwargs)
        ^^^^^^^^^^^^^^^^^^^^^^^^^^^^^^^
  File "/home/mohammad/Documents/code/projects/PlusSaver/.venv/lib/python3.11/site-packages/requests/adapters.py", line 682, in send
    raise ConnectionError(err, request=request)
requests.exceptions.ConnectionError: ('Connection aborted.', ConnectionResetError(104, 'Connection reset by peer'))

The above exception was the direct cause of the following exception:

Traceback (most recent call last):
  File "/home/mohammad/Documents/code/projects/PlusSaver/.venv/lib/python3.11/site-packages/telethon/client/updates.py", line 570, in _dispatch_update
    await callback(event)
  File "/home/mohammad/Documents/code/projects/PlusSaver/modules/handlers/handlers.py", line 401, in get_url
    Instagram(event.message.message).download_post()
  File "/home/mohammad/Documents/code/projects/PlusSaver/modules/downloaders/instagram.py", line 22, in download_post
    post = Post.from_shortcode(self.instagram_client.context, self.url.split("/")[-2])
           ^^^^^^^^^^^^^^^^^^^^^^^^^^^^^^^^^^^^^^^^^^^^^^^^^^^^^^^^^^^^^^^^^^^^^^^^^^^
  File "/home/mohammad/Documents/code/projects/PlusSaver/.venv/lib/python3.11/site-packages/instaloader/structures.py", line 207, in from_shortcode
    post._node = post._full_metadata
                 ^^^^^^^^^^^^^^^^^^^
  File "/home/mohammad/Documents/code/projects/PlusSaver/.venv/lib/python3.11/site-packages/instaloader/structures.py", line 335, in _full_metadata
    self._obtain_metadata()
  File "/home/mohammad/Documents/code/projects/PlusSaver/.venv/lib/python3.11/site-packages/instaloader/structures.py", line 322, in _obtain_metadata
    pic_json = self._context.graphql_query(
               ^^^^^^^^^^^^^^^^^^^^^^^^^^^^
  File "/home/mohammad/Documents/code/projects/PlusSaver/.venv/lib/python3.11/site-packages/instaloader/instaloadercontext.py", line 517, in graphql_query
    resp_json = self.get_json('graphql/query',
                ^^^^^^^^^^^^^^^^^^^^^^^^^^^^^^
  File "/home/mohammad/Documents/code/projects/PlusSaver/.venv/lib/python3.11/site-packages/instaloader/instaloadercontext.py", line 486, in get_json
    raise ConnectionException(error_string) from err
instaloader.exceptions.ConnectionException: JSON Query to graphql/query: ('Connection aborted.', ConnectionResetError(104, 'Connection reset by peer'))
2024-08-17 12:28:10,352 - telethon.network.mtprotosender - INFO - Disconnecting from 149.154.167.92:443/TcpFull...
2024-08-17 12:28:10,353 - telethon.network.mtprotosender - INFO - Disconnection from 149.154.167.92:443/TcpFull complete!
2024-08-17 12:28:10,354 - telethon.network.mtprotosender - INFO - Not disconnecting (already have no connection)
2024-08-17 12:29:16,456 - telethon.client.updates - ERROR - Unhandled exception on get_url
Traceback (most recent call last):
  File "/home/mohammad/Documents/code/projects/PlusSaver/.venv/lib/python3.11/site-packages/instaloader/instaloadercontext.py", line 458, in get_json
    raise ConnectionException(self._response_error(resp))
instaloader.exceptions.ConnectionException: 401 Unauthorized - "fail" status, message "Please wait a few minutes before you try again." when accessing https://www.instagram.com/graphql/query?query_hash=2b0673e0dc4580674a88d426fe00ea90&variables=%7B%22shortcode%22%3A%22C-k9GicvYVm%22%7D

During handling of the above exception, another exception occurred:

Traceback (most recent call last):
  File "/home/mohammad/Documents/code/projects/PlusSaver/.venv/lib/python3.11/site-packages/instaloader/instaloadercontext.py", line 458, in get_json
    raise ConnectionException(self._response_error(resp))
instaloader.exceptions.ConnectionException: 401 Unauthorized - "fail" status, message "Please wait a few minutes before you try again." when accessing https://www.instagram.com/graphql/query?query_hash=2b0673e0dc4580674a88d426fe00ea90&variables=%7B%22shortcode%22%3A%22C-k9GicvYVm%22%7D

During handling of the above exception, another exception occurred:

Traceback (most recent call last):
  File "/home/mohammad/Documents/code/projects/PlusSaver/.venv/lib/python3.11/site-packages/instaloader/instaloadercontext.py", line 458, in get_json
    raise ConnectionException(self._response_error(resp))
instaloader.exceptions.ConnectionException: 401 Unauthorized - "fail" status, message "Please wait a few minutes before you try again." when accessing https://www.instagram.com/graphql/query?query_hash=2b0673e0dc4580674a88d426fe00ea90&variables=%7B%22shortcode%22%3A%22C-k9GicvYVm%22%7D

The above exception was the direct cause of the following exception:

Traceback (most recent call last):
  File "/home/mohammad/Documents/code/projects/PlusSaver/.venv/lib/python3.11/site-packages/telethon/client/updates.py", line 570, in _dispatch_update
    await callback(event)
  File "/home/mohammad/Documents/code/projects/PlusSaver/modules/handlers/handlers.py", line 401, in get_url
    Instagram(event.message.message).download_post()
  File "/home/mohammad/Documents/code/projects/PlusSaver/modules/downloaders/instagram.py", line 22, in download_post
    post = Post.from_shortcode(self.instagram_client.context, self.url.split("/")[-2])
           ^^^^^^^^^^^^^^^^^^^^^^^^^^^^^^^^^^^^^^^^^^^^^^^^^^^^^^^^^^^^^^^^^^^^^^^^^^^
  File "/home/mohammad/Documents/code/projects/PlusSaver/.venv/lib/python3.11/site-packages/instaloader/structures.py", line 207, in from_shortcode
    post._node = post._full_metadata
                 ^^^^^^^^^^^^^^^^^^^
  File "/home/mohammad/Documents/code/projects/PlusSaver/.venv/lib/python3.11/site-packages/instaloader/structures.py", line 335, in _full_metadata
    self._obtain_metadata()
  File "/home/mohammad/Documents/code/projects/PlusSaver/.venv/lib/python3.11/site-packages/instaloader/structures.py", line 322, in _obtain_metadata
    pic_json = self._context.graphql_query(
               ^^^^^^^^^^^^^^^^^^^^^^^^^^^^
  File "/home/mohammad/Documents/code/projects/PlusSaver/.venv/lib/python3.11/site-packages/instaloader/instaloadercontext.py", line 517, in graphql_query
    resp_json = self.get_json('graphql/query',
                ^^^^^^^^^^^^^^^^^^^^^^^^^^^^^^
  File "/home/mohammad/Documents/code/projects/PlusSaver/.venv/lib/python3.11/site-packages/instaloader/instaloadercontext.py", line 482, in get_json
    return self.get_json(path=path, params=params, host=host, session=sess, _attempt=_attempt + 1,
           ^^^^^^^^^^^^^^^^^^^^^^^^^^^^^^^^^^^^^^^^^^^^^^^^^^^^^^^^^^^^^^^^^^^^^^^^^^^^^^^^^^^^^^^
  File "/home/mohammad/Documents/code/projects/PlusSaver/.venv/lib/python3.11/site-packages/instaloader/instaloadercontext.py", line 482, in get_json
    return self.get_json(path=path, params=params, host=host, session=sess, _attempt=_attempt + 1,
           ^^^^^^^^^^^^^^^^^^^^^^^^^^^^^^^^^^^^^^^^^^^^^^^^^^^^^^^^^^^^^^^^^^^^^^^^^^^^^^^^^^^^^^^
  File "/home/mohammad/Documents/code/projects/PlusSaver/.venv/lib/python3.11/site-packages/instaloader/instaloadercontext.py", line 470, in get_json
    raise ConnectionException(error_string) from err
instaloader.exceptions.ConnectionException: JSON Query to graphql/query: 401 Unauthorized - "fail" status, message "Please wait a few minutes before you try again." when accessing https://www.instagram.com/graphql/query?query_hash=2b0673e0dc4580674a88d426fe00ea90&variables=%7B%22shortcode%22%3A%22C-k9GicvYVm%22%7D
2024-08-17 12:30:08,222 - telethon.network.mtprotosender - INFO - Disconnecting from 149.154.167.92:443/TcpFull...
2024-08-17 12:30:08,223 - telethon.network.mtprotosender - INFO - Disconnection from 149.154.167.92:443/TcpFull complete!
2024-08-17 12:30:08,225 - telethon.network.mtprotosender - INFO - Not disconnecting (already have no connection)
2024-08-17 12:56:28,143 - telethon.network.mtprotosender - INFO - Disconnecting from 149.154.167.92:443/TcpFull...
2024-08-17 12:56:28,143 - telethon.network.mtprotosender - INFO - Disconnection from 149.154.167.92:443/TcpFull complete!
2024-08-17 12:56:28,144 - telethon.network.mtprotosender - INFO - Not disconnecting (already have no connection)
